{
 "cells": [
  {
   "cell_type": "code",
   "execution_count": 13,
   "metadata": {},
   "outputs": [],
   "source": [
    "import pandas as pd\n",
    "\n",
    "# Load data from an Excel sheet\n",
    "data = pd.read_excel(r'insurance.xlsx')\n",
    "\n",
    "# Split the data into features (X) and labels (y)\n",
    "X = data.iloc[:, 0:1].values\n",
    "y = data.iloc[:, -1].values\n"
   ]
  },
  {
   "cell_type": "code",
   "execution_count": 15,
   "metadata": {},
   "outputs": [],
   "source": [
    "from sklearn.model_selection import train_test_split\n",
    "from sklearn.preprocessing import StandardScaler\n",
    "\n",
    "# Scale the features\n",
    "scaler = StandardScaler()\n",
    "X = scaler.fit_transform(X)\n",
    "\n",
    "# Split the data into training and testing sets\n",
    "X_train, X_test, y_train, y_test = train_test_split(X, y, test_size=0.2, random_state=42)\n"
   ]
  },
  {
   "cell_type": "code",
   "execution_count": 16,
   "metadata": {},
   "outputs": [
    {
     "name": "stdout",
     "output_type": "stream",
     "text": [
      "Epoch 1/50\n"
     ]
    },
    {
     "ename": "ValueError",
     "evalue": "in user code:\n\n    File \"C:\\Users\\hency\\AppData\\Local\\Packages\\PythonSoftwareFoundation.Python.3.10_qbz5n2kfra8p0\\LocalCache\\local-packages\\Python310\\site-packages\\keras\\src\\engine\\training.py\", line 1338, in train_function  *\n        return step_function(self, iterator)\n    File \"C:\\Users\\hency\\AppData\\Local\\Packages\\PythonSoftwareFoundation.Python.3.10_qbz5n2kfra8p0\\LocalCache\\local-packages\\Python310\\site-packages\\keras\\src\\engine\\training.py\", line 1322, in step_function  **\n        outputs = model.distribute_strategy.run(run_step, args=(data,))\n    File \"C:\\Users\\hency\\AppData\\Local\\Packages\\PythonSoftwareFoundation.Python.3.10_qbz5n2kfra8p0\\LocalCache\\local-packages\\Python310\\site-packages\\keras\\src\\engine\\training.py\", line 1303, in run_step  **\n        outputs = model.train_step(data)\n    File \"C:\\Users\\hency\\AppData\\Local\\Packages\\PythonSoftwareFoundation.Python.3.10_qbz5n2kfra8p0\\LocalCache\\local-packages\\Python310\\site-packages\\keras\\src\\engine\\training.py\", line 1080, in train_step\n        y_pred = self(x, training=True)\n    File \"C:\\Users\\hency\\AppData\\Local\\Packages\\PythonSoftwareFoundation.Python.3.10_qbz5n2kfra8p0\\LocalCache\\local-packages\\Python310\\site-packages\\keras\\src\\utils\\traceback_utils.py\", line 70, in error_handler\n        raise e.with_traceback(filtered_tb) from None\n    File \"C:\\Users\\hency\\AppData\\Local\\Packages\\PythonSoftwareFoundation.Python.3.10_qbz5n2kfra8p0\\LocalCache\\local-packages\\Python310\\site-packages\\keras\\src\\engine\\input_spec.py\", line 280, in assert_input_compatibility\n        raise ValueError(\n\n    ValueError: Exception encountered when calling layer 'sequential' (type Sequential).\n    \n    Input 0 of layer \"dense\" is incompatible with the layer: expected axis -1 of input shape to have value 2, but received input with shape (None, 1)\n    \n    Call arguments received by layer 'sequential' (type Sequential):\n      • inputs=tf.Tensor(shape=(None, 1), dtype=float32)\n      • training=True\n      • mask=None\n",
     "output_type": "error",
     "traceback": [
      "\u001b[1;31m---------------------------------------------------------------------------\u001b[0m",
      "\u001b[1;31mValueError\u001b[0m                                Traceback (most recent call last)",
      "Cell \u001b[1;32mIn[16], line 14\u001b[0m\n\u001b[0;32m     11\u001b[0m model\u001b[39m.\u001b[39mcompile(optimizer\u001b[39m=\u001b[39m\u001b[39m'\u001b[39m\u001b[39madam\u001b[39m\u001b[39m'\u001b[39m, loss\u001b[39m=\u001b[39m\u001b[39m'\u001b[39m\u001b[39mbinary_crossentropy\u001b[39m\u001b[39m'\u001b[39m, metrics\u001b[39m=\u001b[39m[\u001b[39m'\u001b[39m\u001b[39maccuracy\u001b[39m\u001b[39m'\u001b[39m])\n\u001b[0;32m     13\u001b[0m \u001b[39m# Train the model\u001b[39;00m\n\u001b[1;32m---> 14\u001b[0m history \u001b[39m=\u001b[39m model\u001b[39m.\u001b[39;49mfit(X_train, y_train, epochs\u001b[39m=\u001b[39;49m\u001b[39m50\u001b[39;49m, batch_size\u001b[39m=\u001b[39;49m\u001b[39m32\u001b[39;49m, validation_split\u001b[39m=\u001b[39;49m\u001b[39m0.1\u001b[39;49m)\n\u001b[0;32m     16\u001b[0m \u001b[39m# Evaluate the model\u001b[39;00m\n\u001b[0;32m     17\u001b[0m test_loss, test_accuracy \u001b[39m=\u001b[39m model\u001b[39m.\u001b[39mevaluate(X_test, y_test)\n",
      "File \u001b[1;32m~\\AppData\\Local\\Packages\\PythonSoftwareFoundation.Python.3.10_qbz5n2kfra8p0\\LocalCache\\local-packages\\Python310\\site-packages\\keras\\src\\utils\\traceback_utils.py:70\u001b[0m, in \u001b[0;36mfilter_traceback.<locals>.error_handler\u001b[1;34m(*args, **kwargs)\u001b[0m\n\u001b[0;32m     67\u001b[0m     filtered_tb \u001b[39m=\u001b[39m _process_traceback_frames(e\u001b[39m.\u001b[39m__traceback__)\n\u001b[0;32m     68\u001b[0m     \u001b[39m# To get the full stack trace, call:\u001b[39;00m\n\u001b[0;32m     69\u001b[0m     \u001b[39m# `tf.debugging.disable_traceback_filtering()`\u001b[39;00m\n\u001b[1;32m---> 70\u001b[0m     \u001b[39mraise\u001b[39;00m e\u001b[39m.\u001b[39mwith_traceback(filtered_tb) \u001b[39mfrom\u001b[39;00m \u001b[39mNone\u001b[39;00m\n\u001b[0;32m     71\u001b[0m \u001b[39mfinally\u001b[39;00m:\n\u001b[0;32m     72\u001b[0m     \u001b[39mdel\u001b[39;00m filtered_tb\n",
      "File \u001b[1;32m~\\AppData\\Local\\Temp\\__autograph_generated_filetrka3dtm.py:15\u001b[0m, in \u001b[0;36mouter_factory.<locals>.inner_factory.<locals>.tf__train_function\u001b[1;34m(iterator)\u001b[0m\n\u001b[0;32m     13\u001b[0m \u001b[39mtry\u001b[39;00m:\n\u001b[0;32m     14\u001b[0m     do_return \u001b[39m=\u001b[39m \u001b[39mTrue\u001b[39;00m\n\u001b[1;32m---> 15\u001b[0m     retval_ \u001b[39m=\u001b[39m ag__\u001b[39m.\u001b[39mconverted_call(ag__\u001b[39m.\u001b[39mld(step_function), (ag__\u001b[39m.\u001b[39mld(\u001b[39mself\u001b[39m), ag__\u001b[39m.\u001b[39mld(iterator)), \u001b[39mNone\u001b[39;00m, fscope)\n\u001b[0;32m     16\u001b[0m \u001b[39mexcept\u001b[39;00m:\n\u001b[0;32m     17\u001b[0m     do_return \u001b[39m=\u001b[39m \u001b[39mFalse\u001b[39;00m\n",
      "\u001b[1;31mValueError\u001b[0m: in user code:\n\n    File \"C:\\Users\\hency\\AppData\\Local\\Packages\\PythonSoftwareFoundation.Python.3.10_qbz5n2kfra8p0\\LocalCache\\local-packages\\Python310\\site-packages\\keras\\src\\engine\\training.py\", line 1338, in train_function  *\n        return step_function(self, iterator)\n    File \"C:\\Users\\hency\\AppData\\Local\\Packages\\PythonSoftwareFoundation.Python.3.10_qbz5n2kfra8p0\\LocalCache\\local-packages\\Python310\\site-packages\\keras\\src\\engine\\training.py\", line 1322, in step_function  **\n        outputs = model.distribute_strategy.run(run_step, args=(data,))\n    File \"C:\\Users\\hency\\AppData\\Local\\Packages\\PythonSoftwareFoundation.Python.3.10_qbz5n2kfra8p0\\LocalCache\\local-packages\\Python310\\site-packages\\keras\\src\\engine\\training.py\", line 1303, in run_step  **\n        outputs = model.train_step(data)\n    File \"C:\\Users\\hency\\AppData\\Local\\Packages\\PythonSoftwareFoundation.Python.3.10_qbz5n2kfra8p0\\LocalCache\\local-packages\\Python310\\site-packages\\keras\\src\\engine\\training.py\", line 1080, in train_step\n        y_pred = self(x, training=True)\n    File \"C:\\Users\\hency\\AppData\\Local\\Packages\\PythonSoftwareFoundation.Python.3.10_qbz5n2kfra8p0\\LocalCache\\local-packages\\Python310\\site-packages\\keras\\src\\utils\\traceback_utils.py\", line 70, in error_handler\n        raise e.with_traceback(filtered_tb) from None\n    File \"C:\\Users\\hency\\AppData\\Local\\Packages\\PythonSoftwareFoundation.Python.3.10_qbz5n2kfra8p0\\LocalCache\\local-packages\\Python310\\site-packages\\keras\\src\\engine\\input_spec.py\", line 280, in assert_input_compatibility\n        raise ValueError(\n\n    ValueError: Exception encountered when calling layer 'sequential' (type Sequential).\n    \n    Input 0 of layer \"dense\" is incompatible with the layer: expected axis -1 of input shape to have value 2, but received input with shape (None, 1)\n    \n    Call arguments received by layer 'sequential' (type Sequential):\n      • inputs=tf.Tensor(shape=(None, 1), dtype=float32)\n      • training=True\n      • mask=None\n"
     ]
    }
   ],
   "source": [
    "import tensorflow as tf\n",
    "from tensorflow import keras\n",
    "\n",
    "# Build the neural network model\n",
    "model = keras.Sequential([\n",
    "    keras.layers.Dense(units=4, activation='relu', input_dim=2),\n",
    "    keras.layers.Dense(units=1, activation='sigmoid')\n",
    "])\n",
    "\n",
    "# Compile the model\n",
    "model.compile(optimizer='adam', loss='binary_crossentropy', metrics=['accuracy'])\n",
    "\n",
    "# Train the model\n",
    "history = model.fit(X_train, y_train, epochs=50, batch_size=32, validation_split=0.1)\n",
    "\n",
    "# Evaluate the model\n",
    "test_loss, test_accuracy = model.evaluate(X_test, y_test)\n",
    "print(f'Test Accuracy: {test_accuracy:.4f}')\n"
   ]
  }
 ],
 "metadata": {
  "kernelspec": {
   "display_name": "Python 3",
   "language": "python",
   "name": "python3"
  },
  "language_info": {
   "codemirror_mode": {
    "name": "ipython",
    "version": 3
   },
   "file_extension": ".py",
   "mimetype": "text/x-python",
   "name": "python",
   "nbconvert_exporter": "python",
   "pygments_lexer": "ipython3",
   "version": "3.10.11"
  },
  "orig_nbformat": 4
 },
 "nbformat": 4,
 "nbformat_minor": 2
}
